[2024-05-01T00:33:29.054+0000] {taskinstance.py:1165} INFO - Dependencies all met for <TaskInstance: user_processing.create_table scheduled__2024-04-30T00:00:00+00:00 [queued]>
[2024-05-01T00:33:29.071+0000] {taskinstance.py:1165} INFO - Dependencies all met for <TaskInstance: user_processing.create_table scheduled__2024-04-30T00:00:00+00:00 [queued]>
[2024-05-01T00:33:29.071+0000] {taskinstance.py:1362} INFO - 
--------------------------------------------------------------------------------
[2024-05-01T00:33:29.071+0000] {taskinstance.py:1363} INFO - Starting attempt 1 of 1
[2024-05-01T00:33:29.072+0000] {taskinstance.py:1364} INFO - 
--------------------------------------------------------------------------------
[2024-05-01T00:33:29.099+0000] {taskinstance.py:1383} INFO - Executing <Task(PostgresOperator): create_table> on 2024-04-30 00:00:00+00:00
[2024-05-01T00:33:29.119+0000] {standard_task_runner.py:55} INFO - Started process 454 to run task
[2024-05-01T00:33:29.124+0000] {standard_task_runner.py:82} INFO - Running: ['***', 'tasks', 'run', 'user_processing', 'create_table', 'scheduled__2024-04-30T00:00:00+00:00', '--job-id', '4', '--raw', '--subdir', 'DAGS_FOLDER/user_processing.py', '--cfg-path', '/tmp/tmp1izyx95l']
[2024-05-01T00:33:29.126+0000] {standard_task_runner.py:83} INFO - Job 4: Subtask create_table
[2024-05-01T00:33:29.199+0000] {task_command.py:376} INFO - Running <TaskInstance: user_processing.create_table scheduled__2024-04-30T00:00:00+00:00 [running]> on host 3625f7351c61
[2024-05-01T00:33:29.297+0000] {taskinstance.py:1592} INFO - Exporting the following env vars:
AIRFLOW_CTX_DAG_OWNER=***
AIRFLOW_CTX_DAG_ID=user_processing
AIRFLOW_CTX_TASK_ID=create_table
AIRFLOW_CTX_EXECUTION_DATE=2024-04-30T00:00:00+00:00
AIRFLOW_CTX_TRY_NUMBER=1
AIRFLOW_CTX_DAG_RUN_ID=scheduled__2024-04-30T00:00:00+00:00
[2024-05-01T00:33:29.327+0000] {taskinstance.py:1851} ERROR - Task failed with exception
Traceback (most recent call last):
  File "/home/airflow/.local/lib/python3.7/site-packages/airflow/providers/postgres/operators/postgres.py", line 94, in execute
    self.hook.run(self.sql, self.autocommit, parameters=self.parameters)
  File "/home/airflow/.local/lib/python3.7/site-packages/airflow/providers/common/sql/hooks/sql.py", line 288, in run
    with closing(self.get_conn()) as conn:
  File "/home/airflow/.local/lib/python3.7/site-packages/airflow/providers/postgres/hooks/postgres.py", line 88, in get_conn
    conn = deepcopy(self.connection or self.get_connection(conn_id))
  File "/home/airflow/.local/lib/python3.7/site-packages/airflow/hooks/base.py", line 70, in get_connection
    conn = Connection.get_connection_from_secrets(conn_id)
  File "/home/airflow/.local/lib/python3.7/site-packages/airflow/models/connection.py", line 432, in get_connection_from_secrets
    raise AirflowNotFoundException(f"The conn_id `{conn_id}` isn't defined")
airflow.exceptions.AirflowNotFoundException: The conn_id `postgres` isn't defined
[2024-05-01T00:33:29.337+0000] {taskinstance.py:1406} INFO - Marking task as FAILED. dag_id=user_processing, task_id=create_table, execution_date=20240430T000000, start_date=20240501T003329, end_date=20240501T003329
[2024-05-01T00:33:29.356+0000] {standard_task_runner.py:105} ERROR - Failed to execute job 4 for task create_table (The conn_id `postgres` isn't defined; 454)
[2024-05-01T00:33:29.376+0000] {local_task_job.py:164} INFO - Task exited with return code 1
[2024-05-01T00:33:29.403+0000] {local_task_job.py:273} INFO - 0 downstream tasks scheduled from follow-on schedule check
[2024-05-01T00:57:23.928+0000] {taskinstance.py:1165} INFO - Dependencies all met for <TaskInstance: user_processing.create_table scheduled__2024-04-30T00:00:00+00:00 [queued]>
[2024-05-01T00:57:23.951+0000] {taskinstance.py:1165} INFO - Dependencies all met for <TaskInstance: user_processing.create_table scheduled__2024-04-30T00:00:00+00:00 [queued]>
[2024-05-01T00:57:23.951+0000] {taskinstance.py:1362} INFO - 
--------------------------------------------------------------------------------
[2024-05-01T00:57:23.952+0000] {taskinstance.py:1363} INFO - Starting attempt 1 of 1
[2024-05-01T00:57:23.952+0000] {taskinstance.py:1364} INFO - 
--------------------------------------------------------------------------------
[2024-05-01T00:57:23.967+0000] {taskinstance.py:1383} INFO - Executing <Task(PostgresOperator): create_table> on 2024-04-30 00:00:00+00:00
[2024-05-01T00:57:23.974+0000] {standard_task_runner.py:55} INFO - Started process 260 to run task
[2024-05-01T00:57:23.976+0000] {standard_task_runner.py:82} INFO - Running: ['***', 'tasks', 'run', 'user_processing', 'create_table', 'scheduled__2024-04-30T00:00:00+00:00', '--job-id', '3', '--raw', '--subdir', 'DAGS_FOLDER/user_processing.py', '--cfg-path', '/tmp/tmp2ynpdtp1']
[2024-05-01T00:57:23.979+0000] {standard_task_runner.py:83} INFO - Job 3: Subtask create_table
[2024-05-01T00:57:24.052+0000] {task_command.py:376} INFO - Running <TaskInstance: user_processing.create_table scheduled__2024-04-30T00:00:00+00:00 [running]> on host fe27111d44a9
[2024-05-01T00:57:24.131+0000] {taskinstance.py:1592} INFO - Exporting the following env vars:
AIRFLOW_CTX_DAG_OWNER=***
AIRFLOW_CTX_DAG_ID=user_processing
AIRFLOW_CTX_TASK_ID=create_table
AIRFLOW_CTX_EXECUTION_DATE=2024-04-30T00:00:00+00:00
AIRFLOW_CTX_TRY_NUMBER=1
AIRFLOW_CTX_DAG_RUN_ID=scheduled__2024-04-30T00:00:00+00:00
[2024-05-01T00:57:24.152+0000] {taskinstance.py:1851} ERROR - Task failed with exception
Traceback (most recent call last):
  File "/home/airflow/.local/lib/python3.7/site-packages/airflow/providers/postgres/operators/postgres.py", line 94, in execute
    self.hook.run(self.sql, self.autocommit, parameters=self.parameters)
  File "/home/airflow/.local/lib/python3.7/site-packages/airflow/providers/common/sql/hooks/sql.py", line 288, in run
    with closing(self.get_conn()) as conn:
  File "/home/airflow/.local/lib/python3.7/site-packages/airflow/providers/postgres/hooks/postgres.py", line 88, in get_conn
    conn = deepcopy(self.connection or self.get_connection(conn_id))
  File "/home/airflow/.local/lib/python3.7/site-packages/airflow/hooks/base.py", line 70, in get_connection
    conn = Connection.get_connection_from_secrets(conn_id)
  File "/home/airflow/.local/lib/python3.7/site-packages/airflow/models/connection.py", line 432, in get_connection_from_secrets
    raise AirflowNotFoundException(f"The conn_id `{conn_id}` isn't defined")
airflow.exceptions.AirflowNotFoundException: The conn_id `postgres` isn't defined
[2024-05-01T00:57:24.158+0000] {taskinstance.py:1406} INFO - Marking task as FAILED. dag_id=user_processing, task_id=create_table, execution_date=20240430T000000, start_date=20240501T005723, end_date=20240501T005724
[2024-05-01T00:57:24.170+0000] {standard_task_runner.py:105} ERROR - Failed to execute job 3 for task create_table (The conn_id `postgres` isn't defined; 260)
[2024-05-01T00:57:24.189+0000] {local_task_job.py:164} INFO - Task exited with return code 1
[2024-05-01T00:57:24.219+0000] {local_task_job.py:273} INFO - 0 downstream tasks scheduled from follow-on schedule check
[2024-05-01T01:35:16.198+0000] {taskinstance.py:1165} INFO - Dependencies all met for <TaskInstance: user_processing.create_table scheduled__2024-04-30T00:00:00+00:00 [queued]>
[2024-05-01T01:35:16.219+0000] {taskinstance.py:1165} INFO - Dependencies all met for <TaskInstance: user_processing.create_table scheduled__2024-04-30T00:00:00+00:00 [queued]>
[2024-05-01T01:35:16.219+0000] {taskinstance.py:1362} INFO - 
--------------------------------------------------------------------------------
[2024-05-01T01:35:16.220+0000] {taskinstance.py:1363} INFO - Starting attempt 1 of 1
[2024-05-01T01:35:16.220+0000] {taskinstance.py:1364} INFO - 
--------------------------------------------------------------------------------
[2024-05-01T01:35:16.239+0000] {taskinstance.py:1383} INFO - Executing <Task(PostgresOperator): create_table> on 2024-04-30 00:00:00+00:00
[2024-05-01T01:35:16.247+0000] {standard_task_runner.py:55} INFO - Started process 2115 to run task
[2024-05-01T01:35:16.250+0000] {standard_task_runner.py:82} INFO - Running: ['***', 'tasks', 'run', 'user_processing', 'create_table', 'scheduled__2024-04-30T00:00:00+00:00', '--job-id', '10', '--raw', '--subdir', 'DAGS_FOLDER/user_processing.py', '--cfg-path', '/tmp/tmpoa1fasfc']
[2024-05-01T01:35:16.252+0000] {standard_task_runner.py:83} INFO - Job 10: Subtask create_table
[2024-05-01T01:35:16.307+0000] {task_command.py:376} INFO - Running <TaskInstance: user_processing.create_table scheduled__2024-04-30T00:00:00+00:00 [running]> on host fe27111d44a9
[2024-05-01T01:35:16.372+0000] {taskinstance.py:1592} INFO - Exporting the following env vars:
AIRFLOW_CTX_DAG_OWNER=***
AIRFLOW_CTX_DAG_ID=user_processing
AIRFLOW_CTX_TASK_ID=create_table
AIRFLOW_CTX_EXECUTION_DATE=2024-04-30T00:00:00+00:00
AIRFLOW_CTX_TRY_NUMBER=1
AIRFLOW_CTX_DAG_RUN_ID=scheduled__2024-04-30T00:00:00+00:00
[2024-05-01T01:35:16.381+0000] {base.py:71} INFO - Using connection ID 'postgres' for task execution.
[2024-05-01T01:35:16.385+0000] {sql.py:315} INFO - Running statement: 
            CREATE TABLE IF NOT EXISTS users (
                firstname TEXT NOT NULL,
                lastname TEXT NOT NULL,
                country TEXT NOT NULL,
                username TEXT NOT NULL,
                password TEXT NOT NULL,
                email TEXT NOT NULL
            );
        , parameters: None
[2024-05-01T01:35:16.386+0000] {postgres.py:96} INFO - NOTICE:  relation "users" already exists, skipping

[2024-05-01T01:35:16.396+0000] {taskinstance.py:1406} INFO - Marking task as SUCCESS. dag_id=user_processing, task_id=create_table, execution_date=20240430T000000, start_date=20240501T013516, end_date=20240501T013516
[2024-05-01T01:35:16.422+0000] {local_task_job.py:164} INFO - Task exited with return code 0
[2024-05-01T01:35:16.452+0000] {local_task_job.py:273} INFO - 1 downstream tasks scheduled from follow-on schedule check
[2024-05-01T01:37:52.441+0000] {taskinstance.py:1165} INFO - Dependencies all met for <TaskInstance: user_processing.create_table scheduled__2024-04-30T00:00:00+00:00 [queued]>
[2024-05-01T01:37:52.451+0000] {taskinstance.py:1165} INFO - Dependencies all met for <TaskInstance: user_processing.create_table scheduled__2024-04-30T00:00:00+00:00 [queued]>
[2024-05-01T01:37:52.451+0000] {taskinstance.py:1362} INFO - 
--------------------------------------------------------------------------------
[2024-05-01T01:37:52.452+0000] {taskinstance.py:1363} INFO - Starting attempt 1 of 1
[2024-05-01T01:37:52.452+0000] {taskinstance.py:1364} INFO - 
--------------------------------------------------------------------------------
[2024-05-01T01:37:52.465+0000] {taskinstance.py:1383} INFO - Executing <Task(PostgresOperator): create_table> on 2024-04-30 00:00:00+00:00
[2024-05-01T01:37:52.472+0000] {standard_task_runner.py:55} INFO - Started process 2247 to run task
[2024-05-01T01:37:52.476+0000] {standard_task_runner.py:82} INFO - Running: ['***', 'tasks', 'run', 'user_processing', 'create_table', 'scheduled__2024-04-30T00:00:00+00:00', '--job-id', '12', '--raw', '--subdir', 'DAGS_FOLDER/user_processing.py', '--cfg-path', '/tmp/tmp4gs49pr0']
[2024-05-01T01:37:52.478+0000] {standard_task_runner.py:83} INFO - Job 12: Subtask create_table
[2024-05-01T01:37:52.539+0000] {task_command.py:376} INFO - Running <TaskInstance: user_processing.create_table scheduled__2024-04-30T00:00:00+00:00 [running]> on host fe27111d44a9
[2024-05-01T01:37:52.610+0000] {taskinstance.py:1592} INFO - Exporting the following env vars:
AIRFLOW_CTX_DAG_OWNER=***
AIRFLOW_CTX_DAG_ID=user_processing
AIRFLOW_CTX_TASK_ID=create_table
AIRFLOW_CTX_EXECUTION_DATE=2024-04-30T00:00:00+00:00
AIRFLOW_CTX_TRY_NUMBER=1
AIRFLOW_CTX_DAG_RUN_ID=scheduled__2024-04-30T00:00:00+00:00
[2024-05-01T01:37:52.618+0000] {base.py:71} INFO - Using connection ID 'postgres' for task execution.
[2024-05-01T01:37:52.623+0000] {sql.py:315} INFO - Running statement: 
            CREATE TABLE IF NOT EXISTS users (
                firstname TEXT NOT NULL,
                lastname TEXT NOT NULL,
                country TEXT NOT NULL,
                username TEXT NOT NULL,
                password TEXT NOT NULL,
                email TEXT NOT NULL
            );
        , parameters: None
[2024-05-01T01:37:52.625+0000] {postgres.py:96} INFO - NOTICE:  relation "users" already exists, skipping

[2024-05-01T01:37:52.634+0000] {taskinstance.py:1406} INFO - Marking task as SUCCESS. dag_id=user_processing, task_id=create_table, execution_date=20240430T000000, start_date=20240501T013752, end_date=20240501T013752
[2024-05-01T01:37:52.687+0000] {local_task_job.py:164} INFO - Task exited with return code 0
[2024-05-01T01:37:52.714+0000] {local_task_job.py:273} INFO - 1 downstream tasks scheduled from follow-on schedule check
[2024-05-01T01:40:52.927+0000] {taskinstance.py:1165} INFO - Dependencies all met for <TaskInstance: user_processing.create_table scheduled__2024-04-30T00:00:00+00:00 [queued]>
[2024-05-01T01:40:52.936+0000] {taskinstance.py:1165} INFO - Dependencies all met for <TaskInstance: user_processing.create_table scheduled__2024-04-30T00:00:00+00:00 [queued]>
[2024-05-01T01:40:52.936+0000] {taskinstance.py:1362} INFO - 
--------------------------------------------------------------------------------
[2024-05-01T01:40:52.936+0000] {taskinstance.py:1363} INFO - Starting attempt 1 of 1
[2024-05-01T01:40:52.936+0000] {taskinstance.py:1364} INFO - 
--------------------------------------------------------------------------------
[2024-05-01T01:40:52.949+0000] {taskinstance.py:1383} INFO - Executing <Task(PostgresOperator): create_table> on 2024-04-30 00:00:00+00:00
[2024-05-01T01:40:52.955+0000] {standard_task_runner.py:55} INFO - Started process 2406 to run task
[2024-05-01T01:40:52.957+0000] {standard_task_runner.py:82} INFO - Running: ['***', 'tasks', 'run', 'user_processing', 'create_table', 'scheduled__2024-04-30T00:00:00+00:00', '--job-id', '17', '--raw', '--subdir', 'DAGS_FOLDER/user_processing.py', '--cfg-path', '/tmp/tmp3w6ytd_o']
[2024-05-01T01:40:52.958+0000] {standard_task_runner.py:83} INFO - Job 17: Subtask create_table
[2024-05-01T01:40:53.016+0000] {task_command.py:376} INFO - Running <TaskInstance: user_processing.create_table scheduled__2024-04-30T00:00:00+00:00 [running]> on host fe27111d44a9
[2024-05-01T01:40:53.080+0000] {taskinstance.py:1592} INFO - Exporting the following env vars:
AIRFLOW_CTX_DAG_OWNER=***
AIRFLOW_CTX_DAG_ID=user_processing
AIRFLOW_CTX_TASK_ID=create_table
AIRFLOW_CTX_EXECUTION_DATE=2024-04-30T00:00:00+00:00
AIRFLOW_CTX_TRY_NUMBER=1
AIRFLOW_CTX_DAG_RUN_ID=scheduled__2024-04-30T00:00:00+00:00
[2024-05-01T01:40:53.088+0000] {base.py:71} INFO - Using connection ID 'postgres' for task execution.
[2024-05-01T01:40:53.092+0000] {sql.py:315} INFO - Running statement: 
            CREATE TABLE IF NOT EXISTS users (
                firstname TEXT NOT NULL,
                lastname TEXT NOT NULL,
                country TEXT NOT NULL,
                username TEXT NOT NULL,
                password TEXT NOT NULL,
                email TEXT NOT NULL
            );
        , parameters: None
[2024-05-01T01:40:53.093+0000] {postgres.py:96} INFO - NOTICE:  relation "users" already exists, skipping

[2024-05-01T01:40:53.102+0000] {taskinstance.py:1406} INFO - Marking task as SUCCESS. dag_id=user_processing, task_id=create_table, execution_date=20240430T000000, start_date=20240501T014052, end_date=20240501T014053
[2024-05-01T01:40:53.129+0000] {local_task_job.py:164} INFO - Task exited with return code 0
[2024-05-01T01:40:53.154+0000] {local_task_job.py:273} INFO - 1 downstream tasks scheduled from follow-on schedule check
